Workbook
Name sumofGimel1: ' יחמור ג'!$AA$2:$AA$25
Name sumofGimel1: ' - אלקוש ג'!$AA$2:$AA$25

Sheet ריכוז גדודי
A1: 9294 | B1: דוח תחמושת | C1: סוללה א | D1: סוללה ב | E1: סוללה ג | F1: סוללה ד - זעורה | H1: סה"כ גדוד | K1: שצ''ל ירי | L1: סוללה א | M1: סוללה ב | N1: סוללה ג | P1: סה"כ גדוד | S1: דוח תחמושת מעודכן | T1: סוללה א | U1: סוללה ב | V1: סוללה ג | X1: סה"כ גדוד
C2: כפר גלעדי | D2: גומא | E2: יחמור | L2: כפר גלעדי | M2: גומא | N2: אלקוץ | T2: כפר גלעדי | U2: גומא | V2: יחמור
B3: נפיץ M107 | C3: =' תחמושת סוללה א'!Z2 -> 124 | D3: ='תמחושת סוללה ב'!X2 -> 181 | E3: =' יחמור ג'!AA2 -> 224 | F3: #REF! | H3: =E3+D3+C3 -> 529 | K3: נפיץ M107 | M3: 14 | N3: 16 | P3: =N3+M3+L3 -> 30 | S3: נפיץ M107 | T3: =C3-L3 -> 124 | U3: =D3-M3 -> 167 | V3: =E3-N3 -> 208 | X3: =V3+U3+T3 -> 499
B4: נפיץ M107A3 / סרבי | C4: =' תחמושת סוללה א'!Z3 -> 36 | D4: ='תמחושת סוללה ב'!X3-4 -> 49 | E4: =' יחמור ג'!AA3 -> 39 | F4: #REF! | H4: =E4+D4+C4 -> 124 | K4: נפיץ M107A3 / סרבי | N4: =' - אלקוש ג'!AJ3 | P4: =N4+M4+L4 -> 0 | S4: נפיץ M107A3 / סרבי | T4: =C4-L4 -> 36 | U4: =D4-M4 -> 49 | V4: =E4-N4 -> 39 | X4: =V4+U4+T4 -> 124
B5: נפיץ M795 | C5: =' תחמושת סוללה א'!Z4 -> 137 | D5: ='תמחושת סוללה ב'!X4 -> 209 | E5: =' יחמור ג'!AA4 -> 126 | F5: #REF! | H5: =E5+D5+C5 -> 472 | K5: נפיץ M795 | N5: =' - אלקוש ג'!AJ4 | P5: =N5+M5+L5 -> 0 | S5: נפיץ M795 | T5: =C5-L5 -> 137 | U5: =D5-M5 -> 209 | V5: =E5-N5 -> 126 | X5: =V5+U5+T5 -> 472
B6: תאורה M485 | C6: =' תחמושת סוללה א'!Z5 -> 24 | D6: ='תמחושת סוללה ב'!X5 -> 146 | E6: =' יחמור ג'!AA5 -> 158 | F6: #REF! | H6: =E6+D6+C6 -> 328 | K6: תאורה M485 | M6: 10 | N6: =' - אלקוש ג'!AJ5 | P6: =N6+M6+L6 -> 10 | S6: תאורה M485 | T6: =C6-L6 -> 24 | U6: =D6-M6 -> 136 | V6: =E6-N6 -> 158 | X6: =V6+U6+T6 -> 318
B7: עשן M825 | C7: =' תחמושת סוללה א'!Z6 -> 105 | D7: ='תמחושת סוללה ב'!X6 -> 75 | E7: =' יחמור ג'!AA6 -> 0 | F7: #REF! | H7: =E7+D7+C7 -> 180 | K7: עשן M825 | N7: =' - אלקוש ג'!AJ6 | P7: =N7+M7+L7 -> 0 | S7: עשן M825 | T7: =C7-L7 -> 105 | U7: =D7-M7 -> 75 | V7: =E7-N7 -> 0 | X7: =V7+U7+T7 -> 180
B8: דמוי נפיץ | C8: =' תחמושת סוללה א'!Z7 -> 24 | D8: ='תמחושת סוללה ב'!X7 -> 0 | E8: =' יחמור ג'!AA7 -> 0 | F8: #REF! | H8: =E8+D8+C8 -> 24 | K8: דמוי נפיץ | N8: =' - אלקוש ג'!AJ7 | P8: =N8+M8+L8 -> 0 | S8: דמוי נפיץ | T8: =C8-L8 -> 24 | U8: =D8-M8 -> 0 | V8: =E8-N8 -> 0 | X8: =V8+U8+T8 -> 24
B9: עשן הפלטה M150 | C9: =' תחמושת סוללה א'!Z8 -> 0 | D9: ='תמחושת סוללה ב'!X8 -> 144 | E9: =' יחמור ג'!AA8 -> 139 | F9: #REF! | H9: =E9+D9+C9 -> 283 | K9: עשן הפלטה M150 | N9: =' - אלקוש ג'!AJ8 | P9: =N9+M9+L9 -> 0 | S9: עשן הפלטה M150 | T9: =C9-L9 -> 0 | U9: =D9-M9 -> 144 | V9: =E9-N9 -> 139 | X9: =V9+U9+T9 -> 283
B10: נפיץ ארוך טווח M401 | C10: =' תחמושת סוללה א'!Z9 -> 0 | D10: ='תמחושת סוללה ב'!X9 -> 0 | E10: =' יחמור ג'!AA9 -> 0 | F10: #REF! | H10: =E10+D10+C10 -> 0 | K10: נפיץ ארוך טווח M401 | N10: =' - אלקוש ג'!AJ9 | P10: =N10+M10+L10 -> 0 | S10: נפיץ ארוך טווח M401 | T10: =C10-L10 -> 0 | U10: =D10-M10 -> 0 | V10: =E10-N10 -> 0 | X10: =V10+U10+T10 -> 0
B11: M999 | C11: =' תחמושת סוללה א'!Z10 -> 0 | D11: ='תמחושת סוללה ב'!X10 -> 0 | E11: =' יחמור ג'!AA10 -> 0 | F11: #REF! | H11: =E11+D11+C11 -> 0 | K11: M999 | N11: =' - אלקוש ג'!AJ10 | P11: =N11+M11+L11 -> 0 | S11: M999 | T11: =C11-L11 -> 0 | U11: =D11-M11 -> 0 | V11: =E11-N11 -> 0 | X11: =V11+U11+T11 -> 0
B12: 582 | C12: =' תחמושת סוללה א'!Z11 -> 156 | D12: ='תמחושת סוללה ב'!X11 -> 161 | E12: =' יחמור ג'!AA11 -> 150 | F12: #REF! | H12: =E12+D12+C12 -> 467 | K12: 582 | N12: =' - אלקוש ג'!AJ11 | P12: =N12+M12+L12 -> 0 | S12: 582 | T12: =C12-L12 -> 156 | U12: =D12-M12 -> 161 | V12: =E12-N12 -> 150 | X12: =V12+U12+T12 -> 467
B13: 739 | C13: =' תחמושת סוללה א'!Z12 -> 15 | D13: ='תמחושת סוללה ב'!X12 -> 55 | E13: =' יחמור ג'!AA12 -> 12 | F13: #REF! | H13: =E13+D13+C13 -> 82 | K13: 739 | M13: 9 | P13: =N13+M13+L13 -> 9 | S13: 739 | T13: =C13-L13 -> 15 | U13: =D13-M13 -> 46 | V13: =E13-N13 -> 12 | X13: =V13+U13+T13 -> 73
B14: 137 | C14: =' תחמושת סוללה א'!Z13 -> 94 | D14: ='תמחושת סוללה ב'!X13 -> 68 | E14: =' יחמור ג'!AA13 -> 112 | F14: #REF! | H14: =E14+D14+C14 -> 274 | K14: 137 | M14: 15 | N14: =' - אלקוש ג'!AJ13 | P14: =N14+M14+L14 -> 15 | S14: 137 | T14: =C14-L14 -> 94 | U14: =D14-M14 -> 53 | V14: =E14-N14 -> 112 | X14: =V14+U14+T14 -> 259
B15: 762 | C15: =' תחמושת סוללה א'!Z14 -> 0 | D15: ='תמחושת סוללה ב'!X14 -> 272 | E15: =' יחמור ג'!AA14 -> 164 | F15: #REF! | H15: =E15+D15+C15 -> 436 | K15: 762 | N15: =' - אלקוש ג'!AJ14 | P15: =N15+M15+L15 -> 0 | S15: 762 | T15: =C15-L15 -> 0 | U15: =D15-M15 -> 272 | V15: =E15-N15 -> 164 | X15: =V15+U15+T15 -> 436
B16: 147 | C16: =' תחמושת סוללה א'!Z15 -> 0 | D16: ='תמחושת סוללה ב'!X15 -> 0 | E16: =' יחמור ג'!AA15 -> 0 | F16: #REF! | H16: =E16+D16+C16 -> 0 | K16: 147 | N16: =' - אלקוש ג'!AJ15 | P16: =N16+M16+L16 -> 0 | S16: 147 | T16: =C16-L16 -> 0 | U16: =D16-M16 -> 0 | V16: =E16-N16 -> 0 | X16: =V16+U16+T16 -> 0
B17: RTZ148 | C17: =' תחמושת סוללה א'!Z16 -> 136 | D17: ='תמחושת סוללה ב'!X16 -> 96 | E17: =' יחמור ג'!AA16 -> 115 | F17: #REF! | H17: =E17+D17+C17 -> 347 | K17: RTZ148 | N17: 16 | P17: =N17+M17+L17 -> 16 | S17: RTZ148 | T17: =C17-L17 -> 136 | U17: =D17-M17 -> 96 | V17: =E17-N17 -> 99 | X17: =V17+U17+T17 -> 331
B18: סרבי M02P1 | C18: =' תחמושת סוללה א'!Z17 -> 0 | D18: ='תמחושת סוללה ב'!X17 -> 0 | E18: =' יחמור ג'!AA17 -> 0 | F18: #REF! | H18: =E18+D18+C18 -> 0 | K18: סרבי M02P1 | N18: =' - אלקוש ג'!AJ17 | P18: =N18+M18+L18 -> 0 | S18: סרבי M02P1 | T18: =C18-L18 -> 0 | U18: =D18-M18 -> 0 | V18: =E18-N18 -> 0 | X18: =V18+U18+T18 -> 0
B19: 984 | C19: =' תחמושת סוללה א'!Z19 -> 2 | D19: ='תמחושת סוללה ב'!X18 -> 93 | E19: =' יחמור ג'!AA18 -> 144 | H19: =E19+D19+C19 -> 239 | K19: 984 | P19: 0 | S19: 984 | T19: =C19-L19 -> 2 | U19: =D19-M19 -> 93 | V19: =E19-N19 -> 144 | X19: =V19+U19+T19 -> 239
B20: 557 | C20: =' תחמושת סוללה א'!Z18 -> 0 | D20: ='תמחושת סוללה ב'!X19 -> 0 | E20: =' יחמור ג'!AA19 -> 0 | F20: #REF! | H20: =E20+D20+C20 -> 0 | K20: 557 | N20: =' - אלקוש ג'!AJ18 | P20: =N20+M20+L20 -> 0 | S20: 557 | T20: =C20-L20 -> 0 | U20: =D20-M20 -> 0 | V20: =E20-N20 -> 0 | X20: =V20+U20+T20 -> 0
B21: M7 אחוד | C21: =' תחמושת סוללה א'!Z20 -> 1 | D21: ='תמחושת סוללה ב'!X20-4 -> 273 | E21: =' יחמור ג'!AA20 -> 89 | F21: #REF! | H21: =E21+D21+C21 -> 363 | K21: M7 אחוד | M21: 24 | N21: =' - אלקוש ג'!AJ20 | P21: =N21+M21+L21 -> 24 | S21: M7 אחוד | T21: =C21-L21 -> 1 | U21: =D21-M21 -> 249 | V21: =E21-N21 -> 89 | X21: =V21+U21+T21 -> 339
B22: M7 פרוד | C22: =' תחמושת סוללה א'!Z21 -> 164 | D22: ='תמחושת סוללה ב'!X21 -> 157 | E22: =' יחמור ג'!AA21 -> 408 | F22: #REF! | H22: =E22+D22+C22 -> 729 | K22: M7 פרוד | N22: 16 | P22: =N22+M22+L22 -> 16 | S22: M7 פרוד | T22: =C22-L22 -> 164 | U22: =D22-M22 -> 157 | V22: =E22-N22 -> 392 | X22: =V22+U22+T22 -> 713
B23: M9 | C23: =' תחמושת סוללה א'!Z22 -> 285 | D23: ='תמחושת סוללה ב'!X22 -> 332 | E23: =' יחמור ג'!AA22 -> 164 | F23: #REF! | H23: =E23+D23+C23 -> 781 | K23: M9 | N23: =' - אלקוש ג'!AJ22 | P23: =N23+M23+L23 -> 0 | S23: M9 | T23: =C23-L23 -> 285 | U23: =D23-M23 -> 332 | V23: =E23-N23 -> 164 | X23: =V23+U23+T23 -> 781
B24: M10 | C24: =' תחמושת סוללה א'!Z23 -> 0 | D24: ='תמחושת סוללה ב'!X23 -> 0 | E24: =' יחמור ג'!AA23 -> 0 | F24: #REF! | H24: =E24+D24+C24 -> 0 | K24: M10 | N24: =' - אלקוש ג'!AJ23 | P24: =N24+M24+L24 -> 0 | S24: M10 | T24: =C24-L24 -> 0 | U24: =D24-M24 -> 0 | V24: =E24-N24 -> 0 | X24: =V24+U24+T24 -> 0
B25: M231 | C25: =' תחמושת סוללה א'!Z24 -> 76 | D25: ='תמחושת סוללה ב'!X24 -> 0 | E25: =' יחמור ג'!AA24 -> 0 | F25: #REF! | H25: =E25+D25+C25 -> 76 | K25: M231 | N25: =' - אלקוש ג'!AJ24 | P25: =N25+M25+L25 -> 0 | S25: M231 | T25: =C25-L25 -> 76 | U25: =D25-M25 -> 0 | V25: =E25-N25 -> 0 | X25: =V25+U25+T25 -> 76
B26: תחלים | C26: =' תחמושת סוללה א'!Z25 -> 466 | D26: ='תמחושת סוללה ב'!X25 -> 320 | E26: =' יחמור ג'!AA25 -> 1048 | F26: #REF! | H26: =E26+D26+C26 -> 1834 | K26: תחלים | N26: 16 | P26: =N26+M26+L26 -> 16 | S26: תחלים | T26: =C26-L26 -> 466 | U26: =D26-M26 -> 320 | V26: =E26-N26 -> 1032 | X26: =V26+U26+T26 -> 1818
C27: =NOW() -> 46091.382 | L27: =NOW() -> 46091.382 | T27: =NOW() -> 46091.382

Sheet  תחמושת סוללה א
A1: תחמושת | B1: 1א | C1: 1ב | D1: 1ג | E1: 2א | F1: 2ב | G1: 2ג | H1: מפיק | I1: 621 | J1: 140 | K1: ד1ג | L1: ד2א | M1: ד2ב | N1: ד2ג | O1: רמסע 1 | P1: רמסע 2 | Q1: רמסע 3 | R1: רמסע 1783 הגיעה מ531 | S1: רמסע 4 | T1: תפזורת בונקר | U1: סה"כ קנים | V1: סה"כ בונקר | W1: סה"כ
A2: נפיץ M107 | B2: 29 | C2: 16 | D2: 23 | E2: 25 | F2: 31 | G2: 0 | H2: 0 | I2: 0 | J2: 0 | K2: 0 | L2: 0 | M2: 0 | N2: 0 | O2: 0 | P2: 0 | Q2: 0 | S2: 0 | T2: 0 | U2: =SUM(B2:H2) -> 124 | V2: =SUM(I2:T2) -> 0 | W2: =V2+U2 -> 124 | Y2: נפיץ M107 | Z2: =W2 -> 124 | AA2: נפיץ M107
A3: נפיץ M107A3 / סרבי | B3: 11 | C3: 22 | D3: 3 | E3: 0 | F3: 0 | G3: 0 | H3: 0 | I3: 0 | J3: 0 | K3: 0 | L3: 0 | M3: 0 | N3: 0 | O3: 0 | P3: 0 | Q3: 0 | T3: 0 | U3: =SUM(B3:H3) -> 36 | V3: =SUM(I3:T3) -> 0 | W3: =V3+U3 -> 36 | Y3: נפיץ M107A3 / סרבי | Z3: =W3 -> 36 | AA3: נפיץ M107A3 / סרבי
A4: נפיץ M795 | B4: 29 | C4: 21 | D4: 29 | E4: 13 | F4: 13 | G4: 0 | H4: 0 | I4: 16 | J4: 16 | K4: 0 | L4: 0 | M4: 0 | N4: 0 | O4: 0 | P4: 0 | T4: 0 | U4: =SUM(B4:H4) -> 105 | V4: =SUM(I4:T4) -> 32 | W4: =V4+U4 -> 137 | Y4: נפיץ M795 | Z4: =W4 -> 137 | AA4: נפיץ M795
A5: תאורה M485 | B5: 0 | C5: 0 | D5: 8 | E5: 12 | F5: 4 | G5: 0 | H5: 0 | I5: 0 | J5: 0 | K5: 0 | L5: 0 | M5: 0 | N5: 0 | O5: 0 | P5: 0 | Q5: 0 | T5: 0 | U5: =SUM(B5:H5) -> 24 | V5: =SUM(I5:T5) -> 0 | W5: =V5+U5 -> 24 | Y5: תאורה M485 | Z5: =W5 -> 24 | AA5: תאורה M485
A6: עשן M825 | B6: 9 | C6: 5 | D6: 11 | E6: 8 | F6: 16 | G6: 0 | H6: 0 | I6: 0 | J6: 0 | K6: 0 | L6: 0 | M6: 0 | N6: 0 | O6: 56 | P6: 0 | Q6: 0 | T6: 0 | U6: =SUM(B6:H6) -> 49 | V6: =SUM(I6:T6) -> 56 | W6: =V6+U6 -> 105 | Y6: עשן M825 | Z6: =W6 -> 105 | AA6: עשן M825
A7: דמוי נפיץ | B7: 0 | C7: 0 | D7: 0 | E7: 0 | F7: 0 | G7: 0 | H7: 0 | I7: 0 | J7: 0 | K7: 0 | L7: 0 | M7: 0 | N7: 0 | O7: 24 | P7: 0 | T7: 0 | U7: =SUM(B7:H7) -> 0 | V7: =SUM(I7:T7) -> 24 | W7: =V7+U7 -> 24 | Y7: דמוי נפיץ | Z7: =W7 -> 24 | AA7: דמוי נפיץ
A8: עשן הפלטה M150 | B8: 0 | C8: 0 | D8: 0 | E8: 0 | F8: 0 | G8: 0 | H8: 0 | I8: 0 | J8: 0 | K8: 0 | L8: 0 | M8: 0 | N8: 0 | O8: 0 | P8: 0 | Q8: 0 | T8: 0 | U8: =SUM(B8:H8) -> 0 | V8: =SUM(I8:T8) -> 0 | W8: =V8+U8 -> 0 | Y8: עשן הפלטה M150 | Z8: =W8 -> 0 | AA8: עשן הפלטה M150
A9: נפיץ ארוך טווח M401 | B9: 0 | C9: 0 | D9: 0 | E9: 0 | F9: 0 | G9: 0 | H9: 0 | I9: 0 | J9: 0 | K9: 0 | L9: 0 | M9: 0 | N9: 0 | O9: 0 | P9: 0 | Q9: 0 | T9: 0 | U9: =SUM(B9:H9) -> 0 | V9: =SUM(I9:T9) -> 0 | W9: =V9+U9 -> 0 | Y9: נפיץ ארוך טווח M401 | Z9: =W9 -> 0 | AA9: נפיץ ארוך טווח M401
A10: M999 | B10: 0 | C10: 0 | D10: 0 | E10: 0 | F10: 0 | G10: 0 | H10: 0 | I10: 0 | J10: 0 | K10: 0 | L10: 0 | M10: 0 | N10: 0 | O10: 0 | P10: 0 | Q10: 0 | T10: 0 | U10: =SUM(B10:H10) -> 0 | V10: =SUM(I10:T10) -> 0 | W10: =V10+U10 -> 0 | Y10: M999 | Z10: =W10 -> 0 | AA10: M999
A11: 582 | B11: 45 | C11: 6 | D11: 33 | E11: 24 | F11: 24 | G11: 0 | H11: 0 | I11: 0 | J11: 24 | K11: 0 | L11: 0 | M11: 0 | N11: 0 | O11: 0 | P11: 0 | Q11: 0 | T11: 0 | U11: =SUM(B11:H11) -> 132 | V11: =SUM(I11:T11) -> 24 | W11: =V11+U11 -> 156 | Y11: 582 | Z11: =W11 -> 156 | AA11: 582
A12: 739 | B12: 3 | C12: 2 | D12: 2 | E12: 0 | F12: 8 | G12: 0 | H12: 0 | I12: 0 | J12: 0 | K12: 0 | L12: 0 | M12: 0 | N12: 0 | O12: 0 | P12: 0 | Q12: 0 | T12: 0 | U12: =SUM(B12:H12) -> 15 | V12: =SUM(I12:T12) -> 0 | W12: =V12+U12 -> 15 | Y12: 739 | Z12: =W12 -> 15 | AA12: 739
A13: 137 | B13: 14 | C13: 5 | D13: 19 | E13: 28 | F13: 20 | G13: 0 | H13: 0 | I13: 0 | J13: 8 | K13: 0 | L13: 0 | M13: 0 | N13: 0 | O13: 0 | P13: 0 | Q13: 0 | T13: 0 | U13: =SUM(B13:H13) -> 86 | V13: =SUM(I13:T13) -> 8 | W13: =V13+U13 -> 94 | Y13: 137 | Z13: =W13 -> 94 | AA13: 137
A14: 762 | B14: 0 | C14: 0 | D14: 0 | E14: 0 | F14: 0 | G14: 0 | H14: 0 | I14: 0 | J14: 0 | K14: 0 | L14: 0 | M14: 0 | N14: 0 | O14: 0 | P14: 0 | Q14: 0 | T14: 0 | U14: =SUM(B14:H14) -> 0 | V14: =SUM(I14:T14) -> 0 | W14: =V14+U14 -> 0 | Y14: 762 | Z14: =W14 -> 0 | AA14: 762
A15: 147 | B15: 0 | C15: 0 | D15: 0 | E15: 0 | F15: 0 | G15: 0 | H15: 0 | I15: 0 | J15: 0 | K15: 0 | L15: 0 | M15: 0 | N15: 0 | O15: 0 | P15: 0 | Q15: 0 | T15: 0 | U15: =SUM(B15:H15) -> 0 | V15: =SUM(I15:T15) -> 0 | W15: =V15+U15 -> 0 | Y15: 147 | Z15: =W15 -> 0 | AA15: 147
A16: 148 | B16: 24 | C16: 29 | D16: 29 | E16: 32 | F16: 22 | U16: =SUM(B16:H16) -> 136 | V16: =SUM(I16:T16) -> 0 | W16: =V16+U16 -> 136 | Y16: RTZ148 | Z16: =W16 -> 136
A17: סרבי M02P1 | B17: 0 | C17: 0 | D17: 0 | E17: 0 | F17: 0 | G17: 0 | H17: 0 | I17: 0 | J17: 0 | K17: 0 | L17: 0 | M17: 0 | N17: 0 | O17: 0 | P17: 0 | Q17: 0 | T17: 0 | U17: =SUM(B17:H17) -> 0 | V17: =SUM(I17:T17) -> 0 | W17: =V17+U17 -> 0 | Y17: סרבי M02P1 | Z17: =W17 -> 0 | AA17: סרבי M02P1
A18: 984 | U18: =SUM(B18:H18) -> 0 | V18: =SUM(I18:T18) -> 0 | W18: =V18+U18 -> 0 | Y18: 985 | Z18: =W20 -> 0 | AA18: 557
A19: 557 | B19: 0 | C19: 0 | D19: 0 | E19: 0 | F19: 2 | G19: 0 | H19: 0 | I19: 0 | J19: 0 | K19: 0 | L19: 0 | M19: 0 | N19: 0 | O19: 0 | P19: 0 | Q19: 0 | T19: 0 | U19: =SUM(B19:H19) -> 2 | V19: =SUM(I19:T19) -> 0 | W19: =V19+U19 -> 2 | Y19: 557 | Z19: =W19 -> 2
U20: =SUM(B20:H20) -> 0 | V20: =SUM(I20:T20) -> 0 | W20: =V20+U20 -> 0 | Y20: M7 אחוד | Z20: =SUM(W21:W32) -> 1 | AA20: M7 אחוד
A21: M7 אחוד 1-94/99 | B21: 0 | C21: 0 | D21: 0 | E21: 0 | F21: 0 | G21: 0 | I21: 0 | J21: 0 | O21: 0 | U21: =SUM(B21:H21) -> 0 | V21: =SUM(I21:T21) -> 0 | W21: =V21+U21 -> 0 | Y21: M7 פרוד | Z21: =SUM(W33:W37) -> 164 | AA21: M7 פרוד
A22: M7 אחוד 1-98 | B22: 0 | C22: 0 | D22: 0 | E22: 0 | F22: 0 | G22: 0 | I22: 0 | J22: 0 | O22: 0 | U22: =SUM(B22:H22) -> 0 | V22: =SUM(I22:T22) -> 0 | W22: =V22+U22 -> 0 | Y22: M9 | Z22: =SUM(W39:W50) -> 285 | AA22: M9
A23: M7 אחוד 2-24 | B23: 0 | C23: 0 | D23: 0 | E23: 0 | F23: 0 | O23: 0 | U23: =SUM(B23:H23) -> 0 | V23: =SUM(I23:T23) -> 0 | W23: =V23+U23 -> 0 | Y23: M10 | Z23: =W52 -> 0 | AA23: M10
A24: M7 אחוד 01-24 | B24: 0 | C24: 0 | D24: 0 | E24: 0 | F24: 0 | G24: 0 | I24: 0 | J24: 0 | O24: 0 | U24: =SUM(B24:H24) -> 0 | V24: =SUM(I24:T24) -> 0 | W24: =V24+U24 -> 0 | Y24: M231 | Z24: =W53 -> 76 | AA24: M231
A25: M7 אחוד 3-94/99 | B25: 0 | C25: 0 | D25: 0 | E25: 0 | F25: 0 | G25: 0 | I25: 0 | J25: 0 | O25: 0 | U25: =SUM(B25:H25) -> 0 | V25: =SUM(I25:T25) -> 0 | W25: =V25+U25 -> 0 | Y25: תחלים | Z25: =W54 -> 466 | AA25: תחלים
A26: M7 אחוד1-93/97 | B26: 0 | C26: 0 | D26: 0 | E26: 0 | F26: 0 | G26: 0 | I26: 0 | J26: 0 | O26: 0 | U26: =SUM(B26:H26) -> 0 | V26: =SUM(I26:T26) -> 0 | W26: =V26+U26 -> 0
A27: M7 אחוד 1-94/99 | B27: 0 | C27: 0 | D27: 0 | E27: 0 | F27: 0 | G27: 0 | I27: 0 | J27: 0 | O27: 0 | U27: =SUM(B27:H27) -> 0 | V27: =SUM(I27:T27) -> 0 | W27: =V27+U27 -> 0
A28: M7 אחוד 2-93/97 | B28: 0 | C28: 0 | D28: 0 | E28: 0 | F28: 0 | G28: 0 | I28: 0 | J28: 0 | O28: 0 | U28: =SUM(B28:H28) -> 0 | V28: =SUM(I28:T28) -> 0 | W28: =V28+U28 -> 0
A29: M7 אחוד 2-99 | B29: 0 | C29: 0 | D29: 0 | E29: 0 | F29: 0 | G29: 0 | I29: 0 | J29: 0 | O29: 0 | U29: =SUM(B29:H29) -> 0 | V29: =SUM(I29:T29) -> 0 | W29: =V29+U29 -> 0
A30: M7 אחוד 1-94/99 | B30: 0 | C30: 0 | D30: 0 | E30: 0 | F30: 0 | G30: 0 | I30: 0 | J30: 0 | O30: 0 | U30: =SUM(B30:H30) -> 0 | V30: =SUM(I30:T30) -> 0 | W30: =V30+U30 -> 0
A31: M7 אחוד 68746/24 | B31: 0 | C31: 0 | D31: 0 | E31: 0 | F31: 0 | G31: 0 | I31: 0 | J31: 0 | O31: 0 | U31: =SUM(B31:H31) -> 0 | V31: =SUM(I31:T31) -> 0 | W31: =V31+U31 -> 0
A32: M7 אחוד 1-24 | B32: 0 | C32: 1 | D32: 0 | E32: 0 | F32: 0 | G32: 0 | I32: 0 | J32: 0 | O32: 0 | U32: =SUM(B32:H32) -> 1 | V32: =SUM(I32:T32) -> 0 | W32: =V32+U32 -> 1
A33: M7 פרוד 22/25 | C33: 48 | D33: 36 | E33: 37 | U33: =SUM(B33:H33) -> 121 | V33: =SUM(I33:T33) -> 0 | W33: =V33+U33 -> 121
A34: פרוד D001-061 | D34: 9 | E34: 0 | F34: 6 | U34: =SUM(B34:H34) -> 15 | V34: =SUM(I34:T34) -> 0 | W34: =V34+U34 -> 15
A35: M7 פרוד 14-25 | B35: 22 | C35: 6 | D35: 0 | E35: 0 | F35: 0 | G35: 0 | I35: 0 | J35: 0 | O35: 0 | U35: =SUM(B35:H35) -> 28 | V35: =SUM(I35:T35) -> 0 | W35: =V35+U35 -> 28
A36: M7 פרוד2-94/97 | B36: 0 | C36: 0 | D36: 0 | E36: 0 | F36: 0 | G36: 0 | I36: 0 | J36: 0 | O36: 0 | U36: =SUM(B36:H36) -> 0 | V36: =SUM(I36:T36) -> 0 | W36: =V36+U36 -> 0
A37: פרוד 1-98 | B37: 0 | C37: 0 | D37: 0 | E37: 0 | F37: 0 | G37: 0 | I37: 0 | J37: 0 | O37: 0 | U37: =SUM(B37:H37) -> 0 | V37: =SUM(I37:T37) -> 0 | W37: =V37+U37 -> 0
U38: =SUM(B38:H38) -> 0 | V38: =SUM(I38:T38) -> 0 | W38: =V38+U38 -> 0
A39: M9 4-99/02 | B39: 0 | C39: 0 | D39: 0 | E39: 0 | F39: 0 | G39: 0 | I39: 0 | J39: 0 | U39: =SUM(B39:H39) -> 0 | V39: =SUM(I39:T39) -> 0 | W39: =V39+U39 -> 0
A40: M9 5-96/84 | B40: 0 | C40: 0 | D40: 0 | E40: 0 | F40: 0 | G40: 0 | I40: 0 | J40: 0 | U40: =SUM(B40:H40) -> 0 | V40: =SUM(I40:T40) -> 0 | W40: =V40+U40 -> 0
...

Sheet תמחושת סוללה ב
A1: תחמושת | B1: 1א | D1: 1ג | E1: 2א | F1: 2ב | G1: 2ג | H1: מפיק | I1: ד1 - 751644 | J1: רמסע 1731 | K1: רמסע 326 | L1: רמסע 776 | M1: ד2 - 757584 | N1: ד2ג - 752048 | O1: רמסע 1 - 30722 | P1: רמסע 540 | Q1: רמסע 1607 | R1: רמסע 525 | S1: סה"כ קנים | T1: סה"כ בונקר | U1: סה"כ
A2: נפיץ M107 | B2: 18 | D2: 29 | E2: 25 | F2: 13 | G2: 16 | L2: 80 | M2: 0 | S2: =SUM(B2:H2) -> 101 | T2: =SUM(I2:R2) -> 80 | U2: =T2+S2 -> 181 | W2: נפיץ M107 | X2: =U2 -> 181
A3: נפיץ M107A3 / סרבי | B3: 15 | D3: 3 | E3: 14 | F3: 7 | G3: =19-5 -> 14 | N3: 0 | R3: 0 | S3: =SUM(B3:H3) -> 53 | T3: =SUM(I3:R3) -> 0 | U3: =T3+S3 -> 53 | W3: =A3 -> נפיץ M107A3 / סרבי | X3: =U3 -> 53
A4: נפיץ M795 | B4: 37 | D4: 29 | E4: 37 | F4: 29 | G4: 37 | I4: 16 | M4: 0 | N4: 0 | Q4: 24 | S4: =SUM(B4:H4) -> 169 | T4: =SUM(I4:R4) -> 40 | U4: =T4+S4 -> 209 | W4: נפיץ M795 | X4: =U4 -> 209
A5: תאורה M485 | B5: 16 | D5: 10 | E5: 16 | F5: 24 | G5: 16 | P5: 64 | S5: =SUM(B5:H5) -> 82 | T5: =SUM(I5:R5) -> 64 | U5: =T5+S5 -> 146 | W5: תאורה M485 | X5: =U5 -> 146
A6: עשן M825 | B6: 17 | D6: 8 | E6: 14 | F6: 14 | G6: 22 | O6: 0 | S6: =SUM(B6:H6) -> 75 | T6: =SUM(I6:R6) -> 0 | U6: =T6+S6 -> 75 | W6: עשן M825 | X6: =U6 -> 75
A7: דמוי נפיץ | S7: =SUM(B7:H7) -> 0 | T7: =SUM(I7:R7) -> 0 | U7: =T7+S7 -> 0 | W7: דמוי נפיץ | X7: =U7 -> 0
A8: עשן הפלטה M150 | B8: 0 | K8: 144 | S8: =SUM(B8:H8) -> 0 | T8: =SUM(I8:R8) -> 144 | U8: =T8+S8 -> 144 | W8: עשן הפלטה M150 | X8: =U8 -> 144
A9: נפיץ ארוך טווח M401 | S9: =SUM(B9:H9) -> 0 | T9: =SUM(I9:R9) -> 0 | U9: =T9+S9 -> 0 | W9: נפיץ ארוך טווח M401 | X9: =U9 -> 0
A10: M999 | D10: 0 | E10: 0 | F10: 0 | G10: 0 | H10: 0 | I10: 0 | K10: 0 | L10: 0 | M10: 0 | N10: 0 | O10: 0 | P10: 0 | Q10: 0 | R10: 0 | S10: =SUM(B10:H10) -> 0 | T10: =SUM(I10:R10) -> 0 | U10: =T10+S10 -> 0 | W10: M999 | X10: =U10 -> 0
A11: 582 | B11: 8 | D11: 36 | E11: 40 | F11: 45 | G11: 16 | I11: 16 | M11: 0 | N11: 0 | Q11: 0 | S11: =SUM(B11:H11) -> 145 | T11: =SUM(I11:R11) -> 16 | U11: =T11+S11 -> 161 | W11: 582 | X11: =U11 -> 161
A12: 739 | B12: 10 | D12: 1 | E12: 22 | F12: 8 | G12: =14 -> 14 | N12: 0 | R12: 0 | S12: =SUM(B12:H12) -> 55 | T12: =SUM(I12:R12) -> 0 | U12: =T12+S12 -> 55 | W12: 739 | X12: =U12 -> 55
A13: 137 | B13: 23 | E13: 17 | F13: 14 | G13: 14 | N13: 0 | S13: =SUM(B13:H13) -> 68 | T13: =SUM(I13:R13) -> 0 | U13: =T13+S13 -> 68 | W13: 137 | X13: =U13 -> 68
A14: 762 | B14: 29 | D14: 51 | E14: 16 | F14: 16 | G14: 16 | K14: 144 | P14: 0 | S14: =SUM(B14:H14) -> 128 | T14: =SUM(I14:R14) -> 144 | U14: =T14+S14 -> 272 | W14: 762 | X14: =U14 -> 272
A15: 147 | S15: =SUM(B15:H15) -> 0 | T15: =SUM(I15:R15) -> 0 | U15: =T15+S15 -> 0 | W15: 147 | X15: =U15 -> 0
A16: 148 | L16: =144-48 -> 96 | S16: =SUM(B16:H16) -> 0 | T16: =SUM(I16:R16) -> 96 | U16: =T16+S16 -> 96 | W16: 148 | X16: =U16 -> 96
A17: סרבי M02P1 | S17: =SUM(B17:H17) -> 0 | T17: =SUM(I17:R17) -> 0 | U17: =T17+S17 -> 0 | W17: סרבי M02P1 | X17: =U17 -> 0
A18: 984 | B18: 31 | D18: 3 | E18: 20 | F18: 23 | G18: 16 | S18: =SUM(B18:H18) -> 93 | T18: =SUM(I18:R18) -> 0 | U18: =T18+S18 -> 93 | W18: 984 | X18: =U18 -> 93
A19: 557 | D19: 0 | E19: 0 | F19: 0 | H19: 0 | I19: 0 | K19: 0 | L19: 0 | M19: 0 | N19: 0 | O19: 0 | P19: 0 | Q19: 0 | S19: =SUM(B19:H19) -> 0 | T19: =SUM(I19:R19) -> 0 | U19: =T19+S19 -> 0 | W19: 557 | X19: =U19 -> 0
W20: M7 אחוד | X20: =SUM(U21:U31) -> 277
A21: M7 אחוד 4-91/97 | E21: 15 | F21: 20 | S21: =SUM(B21:H21) -> 35 | T21: =SUM(I21:R21) -> 0 | U21: =T21+S21 -> 35 | W21: M7 פרוד | X21: =SUM(U32:U36) -> 157
A22: M7 אחוד 1-98 | S22: =SUM(B22:H22) -> 0 | T22: =SUM(I22:R22) -> 0 | U22: =T22+S22 -> 0 | W22: M9 | X22: =SUM(U38:AF46) -> 332
A23: M7 אחוד 01-98 | S23: =SUM(B23:H23) -> 0 | T23: =SUM(I23:R23) -> 0 | U23: =T23+S23 -> 0 | W23: M10 | X23: =U48 -> 0
A24: M7 אחוד 3-94/99 | S24: =SUM(B24:H24) -> 0 | T24: =SUM(I24:R24) -> 0 | U24: =T24+S24 -> 0 | W24: M231 | X24: =U49 -> 0
A25: M7 אחוד1-93/97 | S25: =SUM(B25:H25) -> 0 | T25: =SUM(I25:R25) -> 0 | U25: =T25+S25 -> 0 | W25: תחלים | X25: =U50 -> 320
A26: M7 אחוד 1-94/99 | S26: =SUM(B26:H26) -> 0 | T26: =SUM(I26:R26) -> 0 | U26: =T26+S26 -> 0
A27: M7 אחוד 2-93/97 | S27: =SUM(B27:H27) -> 0 | T27: =SUM(I27:R27) -> 0 | U27: =T27+S27 -> 0
A28: M7 אחוד 4-91-25 | E28: 24 | F28: 24 | G28: =24-5 -> 19 | K28: 96 | L28: 72 | S28: =SUM(B28:H28) -> 67 | T28: =SUM(I28:R28) -> 168 | U28: =T28+S28 -> 235
A29: M7 אחוד 1-94/99 | S29: =SUM(B29:H29) -> 0 | T29: =SUM(I29:R29) -> 0 | U29: =T29+S29 -> 0
A30: M7 אחוד 2/24 | D30: 2 | E30: 5 | S30: =SUM(B30:H30) -> 7 | T30: =SUM(I30:R30) -> 0 | U30: =T30+S30 -> 7
A31: M7אחוד 1-24 | S31: =SUM(B31:H31) -> 0 | T31: =SUM(I31:R31) -> 0 | U31: =T31+S31 -> 0
A32: M7 פרוד 1-93/97 | S32: =SUM(B32:H32) -> 0 | T32: =SUM(I32:R32) -> 0 | U32: =T32+S32 -> 0
A33: M7 פרוד 062 | B33: 29 | E33: 14 | F33: 22 | G33: 24 | S33: =SUM(B33:H33) -> 89 | T33: =SUM(I33:R33) -> 0 | U33: =T33+S33 -> 89
A34: M7 פרוד22-25 | D34: 20 | K34: 48 | R34: 0 | S34: =SUM(B34:H34) -> 20 | T34: =SUM(I34:R34) -> 48 | U34: =T34+S34 -> 68
A35: M7 פרוד2-94/97 | S35: =SUM(B35:H35) -> 0 | T35: =SUM(I35:R35) -> 0 | U35: =T35+S35 -> 0
A36: פרוד 1-98 | S36: =SUM(B36:H36) -> 0 | T36: =SUM(I36:R36) -> 0 | U36: =T36+S36 -> 0
A38: M9 4-99/02 | S38: =SUM(B38:H38) -> 0 | T38: =SUM(I38:R38) -> 0 | U38: =T38+S38 -> 0
A39: M9 5-96/84 | S39: =SUM(B39:H39) -> 0 | T39: =SUM(I39:R39) -> 0 | U39: =T39+S39 -> 0
A40: M9 10-99/84 | S40: =SUM(B40:H40) -> 0 | T40: =SUM(I40:R40) -> 0 | U40: =T40+S40 -> 0
A41: M9 5-99/85 | S41: =SUM(B41:H41) -> 0 | T41: =SUM(I41:R41) -> 0 | U41: =T41+S41 -> 0
...

Sheet  יחמור ג
A1: תחמושת | B1: 813375 | C1: 814553 | D1: 813308 | E1: 813207 | F1: 813217 | G1: 813038 | H1: מפיק | I1: 758115 ד | J1: 758134 ד | K1: 752525 ד | L1: 752366 ד | M1: ד2ב | N1: ד2ג | O1: רמסע 1786 | P1: רמסע 1202 | Q1: בצד | R1: רמסע 211 | S1: רמסע 300514 | U1: תפזורת בונקר | V1: סה"כ קנים | W1: סה"כ בונקר | X1: סה"כ
A2: נפיץ M107 | B2: 30 | C2: 23 | D2: 27 | R2: 144 | V2: =SUM(B2:H2) -> 80 | W2: =SUM(I2:U2) -> 144 | X2: =W2+V2 -> 224 | Z2: נפיץ M107 | AA2: =X2 -> 224
A3: נפיץ M107A3 / סרבי | F3: 16 | G3: 23 | V3: =SUM(B3:H3) -> 39 | W3: =SUM(I3:U3) -> 0 | X3: =W3+V3 -> 39 | Z3: =A3 -> נפיץ M107A3 / סרבי | AA3: =X3 -> 39
A4: נפיץ M795 | B4: 13 | C4: 13 | D4: 13 | E4: 13 | F4: 13 | G4: 13 | L4: 48 | V4: =SUM(B4:H4) -> 78 | W4: =SUM(I4:U4) -> 48 | X4: =W4+V4 -> 126 | Z4: נפיץ M795 | AA4: =X4 -> 126
A5: תאורה M485 | B5: 8 | C5: 8 | D5: 10 | E5: 6 | F5: 16 | G5: 14 | L5: 24 | O5: 72 | V5: =SUM(B5:H5) -> 62 | W5: =SUM(I5:U5) -> 96 | X5: =W5+V5 -> 158 | Z5: תאורה M485 | AA5: =X5 -> 158
A6: עשן M825 | V6: =SUM(B6:H6) -> 0 | W6: =SUM(I6:U6) -> 0 | X6: =W6+V6 -> 0 | Z6: עשן M825 | AA6: =X6 -> 0
A7: דמוי נפיץ | V7: =SUM(B7:H7) -> 0 | W7: =SUM(I7:U7) -> 0 | X7: =W7+V7 -> 0 | Z7: דמוי נפיץ | AA7: =X7 -> 0
A8: עשן הפלטה M150 | B8: 20 | C8: 20 | D8: 20 | F8: 13 | G8: 18 | O8: 48 | V8: =SUM(B8:H8) -> 91 | W8: =SUM(I8:U8) -> 48 | X8: =W8+V8 -> 139 | Z8: עשן הפלטה M150 | AA8: =X8 -> 139
A9: נפיץ ארוך טווח M401 | V9: =SUM(B9:H9) -> 0 | W9: =SUM(I9:U9) -> 0 | X9: =W9+V9 -> 0 | Z9: נפיץ ארוך טווח M401 | AA9: =X9 -> 0
A10: M999 | V10: =SUM(B10:H10) -> 0 | W10: =SUM(I10:U10) -> 0 | X10: =W10+V10 -> 0 | Z10: M999 | AA10: =X10 -> 0
A11: 582 | B11: 16 | C11: 8 | D11: 14 | E11: 24 | F11: 16 | G11: 40 | L11: 32 | V11: =SUM(B11:H11) -> 118 | W11: =SUM(I11:U11) -> 32 | X11: =W11+V11 -> 150 | Z11: 582 | AA11: =X11 -> 150
A12: 739 | F12: 12 | V12: =SUM(B12:H12) -> 12 | W12: =SUM(I12:U12) -> 0 | X12: =W12+V12 -> 12 | Z12: 739 | AA12: =X12 -> 12
A13: 137 | B13: 16 | C13: 16 | D13: 16 | E13: 8 | F13: 8 | G13: 16 | L13: 32 | V13: =SUM(B13:H13) -> 80 | W13: =SUM(I13:U13) -> 32 | X13: =W13+V13 -> 112 | Z13: 137 | AA13: =X13 -> 112
A14: 762 | B14: 12 | C14: 14 | D14: 29 | F14: 21 | G14: 24 | O14: 64 | V14: =SUM(B14:H14) -> 100 | W14: =SUM(I14:U14) -> 64 | X14: =W14+V14 -> 164 | Z14: 762 | AA14: =X14 -> 164
A15: 147 | V15: =SUM(B15:H15) -> 0 | W15: =SUM(I15:U15) -> 0 | X15: =W15+V15 -> 0 | Z15: 147 | AA15: =X15 -> 0
A16: 148 | B16: 30 | C16: 23 | D16: 23 | F16: 16 | G16: 23 | V16: =SUM(B16:H16) -> 115 | W16: =SUM(I16:U16) -> 0 | X16: =W16+V16 -> 115 | Z16: RTZ148 | AA16: =X16 -> 115
A17: סרבי M02P1 | V17: =SUM(B17:H17) -> 0 | W17: =SUM(I17:U17) -> 0 | X17: =W17+V17 -> 0 | Z17: סרבי M02P1 | AA17: =X17 -> 0
A18: 984 | R18: 144 | V18: =SUM(B18:H18) -> 0 | W18: =SUM(I18:U18) -> 144 | X18: =W18+V18 -> 144 | Z18: 984 | AA18: =X18 -> 144
A19: 557 | V19: =SUM(B19:H19) -> 0 | W19: =SUM(I19:U19) -> 0 | X19: =W19+V19 -> 0 | Z19: 557 | AA19: =X19 -> 0
Z20: M7 אחוד | AA20: =SUM(X21:X30) -> 89
A21: M7 4-91-25 אחוד | B21: 20 | C21: 18 | D21: 33 | V21: =SUM(B21:H21) -> 71 | W21: =SUM(I21:U21) -> 0 | X21: =W21+V21 -> 71 | Z21: M7 פרוד | AA21: =SUM(X31:X34) -> 408
A22: M7 אחוד 1-98 | V22: =SUM(B22:H22) -> 0 | W22: =SUM(I22:U22) -> 0 | X22: =W22+V22 -> 0 | Z22: M9 | AA22: =SUM(X36:X44) -> 164
A23: M7 אחוד 01-98 | V23: =SUM(B23:H23) -> 0 | W23: =SUM(I23:U23) -> 0 | X23: =W23+V23 -> 0 | Z23: M10 | AA23: =X46 -> 0
A24: M7 אחוד 3-94/99 | V24: =SUM(B24:H24) -> 0 | W24: =SUM(I24:U24) -> 0 | X24: =W24+V24 -> 0 | Z24: M231 | AA24: =X47 -> 0
A25: M7 אחוד1-93/97 | V25: =SUM(B25:H25) -> 0 | W25: =SUM(I25:U25) -> 0 | X25: =W25+V25 -> 0 | Z25: תחלים | AA25: =X48 -> 1048
A26: M7 אחוד 1-94/99 | V26: =SUM(B26:H26) -> 0 | W26: =SUM(I26:U26) -> 0 | X26: =W26+V26 -> 0
A27: M7 אחוד 2-93/97 | V27: =SUM(B27:H27) -> 0 | W27: =SUM(I27:U27) -> 0 | X27: =W27+V27 -> 0
A28: M7 אחוד 2-99 | V28: =SUM(B28:H28) -> 0 | W28: =SUM(I28:U28) -> 0 | X28: =W28+V28 -> 0
A29: M7 3-91-25 אחוד | G29: 18 | V29: =SUM(B29:H29) -> 18 | W29: =SUM(I29:U29) -> 0 | X29: =W29+V29 -> 18
A30: M7 אחוד 2/24 | V30: =SUM(B30:H30) -> 0 | W30: =SUM(I30:U30) -> 0 | X30: =W30+V30 -> 0
A31: M7 פרוד SB 22-25 | R31: 144 | V31: =SUM(B31:H31) -> 0 | W31: =SUM(I31:U31) -> 144 | X31: =W31+V31 -> 144
A32: M7 פרוד 14-25 | O32: 120 | V32: =SUM(B32:H32) -> 0 | W32: =SUM(I32:U32) -> 120 | X32: =W32+V32 -> 120
A33: M7 פרוד 68746-94/24 | B33: 29 | C33: 29 | D33: 28 | F33: 29 | G33: 29 | V33: =SUM(B33:H33) -> 144 | W33: =SUM(I33:U33) -> 0 | X33: =W33+V33 -> 144
A34: פרוד 1-98 | V34: =SUM(B34:H34) -> 0 | W34: =SUM(I34:U34) -> 0 | X34: =W34+V34 -> 0
A36: M9 4-99/02 | V36: =SUM(B36:H36) -> 0 | W36: =SUM(I36:U36) -> 0 | X36: =W36+V36 -> 0
A37: M9 5-96/84 | V37: =SUM(B37:H37) -> 0 | W37: =SUM(I37:U37) -> 0 | X37: =W37+V37 -> 0
A38: M9 10-99/84 | V38: =SUM(B38:H38) -> 0 | W38: =SUM(I38:U38) -> 0 | X38: =W38+V38 -> 0
A39: M9 5-99/85 | V39: =SUM(B39:H39) -> 0 | W39: =SUM(I39:U39) -> 0 | X39: =W39+V39 -> 0
A40: M9 1-07 | P40: 43 | V40: =SUM(B40:H40) -> 0 | W40: =SUM(I40:U40) -> 43 | X40: =W40+V40 -> 43
A41: M9 3-99/88 | P41: 16 | V41: =SUM(B41:H41) -> 0 | W41: =SUM(I41:U41) -> 16 | X41: =W41+V41 -> 16
...

Sheet קישור לגוגל פורמז - אגמי 
A1: https://forms.gle/QV2RxuF8yAs11UDH9

Sheet  - אלקוש ג
A1: תחמושת | B1: 813375 | C1: 814553 | D1: 813308 | E1: 813207 | F1: 813217 | G1: 813038 | H1: מפיק | I1: 758115 ד | J1: 758134 ד | K1: 752525 ד | L1: 752366 ד | M1: ד2ב | N1: ד2ג | O1: רמסע 1022 | P1: רמסע 1464 | Q1: רמסע 657 | R1: רמסע 211 | S1: רמסע 300514 | U1: תפזורת בונקר | V1: סה"כ קנים | W1: סה"כ בונקר | X1: סה"כ
A2: נפיץ M107 | B2: 19 | C2: 16 | D2: 5 | E2: 25 | F2: 16 | G2: 12 | R2: 144 | V2: =SUM(B2:H2) -> 93 | W2: =SUM(I2:U2) -> 144 | X2: =W2+V2 -> 237 | Z2: נפיץ M107 | AA2: =X2 -> 237
A3: נפיץ M107A3 / סרבי | Q3: 144 | V3: =SUM(B3:H3) -> 0 | W3: =SUM(I3:U3) -> 144 | X3: =W3+V3 -> 144 | Z3: =A3 -> נפיץ M107A3 / סרבי | AA3: =X3 -> 144
A4: נפיץ M795 | B4: 13 | C4: 13 | D4: 13 | E4: 13 | F4: 13 | G4: 13 | I4: 16 | J4: 16 | L4: 16 | V4: =SUM(B4:H4) -> 78 | W4: =SUM(I4:U4) -> 48 | X4: =W4+V4 -> 126 | Z4: נפיץ M795 | AA4: =X4 -> 126
A5: תאורה M485 | B5: 8 | C5: 16 | D5: 8 | F5: 8 | G5: 8 | V5: =SUM(B5:H5) -> 48 | W5: =SUM(I5:U5) -> 0 | X5: =W5+V5 -> 48 | Z5: תאורה M485 | AA5: =X5 -> 48
A6: עשן M825 | V6: =SUM(B6:H6) -> 0 | W6: =SUM(I6:U6) -> 0 | X6: =W6+V6 -> 0 | Z6: עשן M825 | AA6: =X6 -> 0
A7: דמוי נפיץ | V7: =SUM(B7:H7) -> 0 | W7: =SUM(I7:U7) -> 0 | X7: =W7+V7 -> 0 | Z7: דמוי נפיץ | AA7: =X7 -> 0
A8: עשן הפלטה M150 | B8: 16 | C8: 16 | D8: 16 | F8: 16 | G8: 16 | O8: 64 | V8: =SUM(B8:H8) -> 80 | W8: =SUM(I8:U8) -> 64 | X8: =W8+V8 -> 144 | Z8: עשן הפלטה M150 | AA8: =X8 -> 144
A9: נפיץ ארוך טווח M401 | V9: =SUM(B9:H9) -> 0 | W9: =SUM(I9:U9) -> 0 | X9: =W9+V9 -> 0 | Z9: נפיץ ארוך טווח M401 | AA9: =X9 -> 0
A10: M999 | V10: =SUM(B10:H10) -> 0 | W10: =SUM(I10:U10) -> 0 | X10: =W10+V10 -> 0 | Z10: M999 | AA10: =X10 -> 0
A11: 582 | B11: 31 | C11: 19 | D11: 14 | E11: 24 | F11: 24 | G11: 5 | I11: 24 | J11: 24 | L11: 32 | V11: =SUM(B11:H11) -> 117 | W11: =SUM(I11:U11) -> 80 | X11: =W11+V11 -> 197 | Z11: 582 | AA11: =X11 -> 197
A12: 739 | B12: 11 | C12: 0 | D12: 0 | E12: 8 | F12: 12 | G12: 0 | V12: =SUM(B12:H12) -> 31 | W12: =SUM(I12:U12) -> 0 | X12: =W12+V12 -> 31 | Z12: 739 | AA12: =X12 -> 31
A13: 137 | B13: 13 | C13: 8 | D13: 8 | E13: 8 | F13: 8 | G13: 8 | I13: 32 | J13: 24 | L13: 32 | V13: =SUM(B13:H13) -> 53 | W13: =SUM(I13:U13) -> 88 | X13: =W13+V13 -> 141 | Z13: 137 | AA13: =X13 -> 141
A14: 762 | B14: 8 | C14: 16 | D14: 16 | F14: 16 | G14: 16 | O14: 72 | V14: =SUM(B14:H14) -> 72 | W14: =SUM(I14:U14) -> 72 | X14: =W14+V14 -> 144 | Z14: 762 | AA14: =X14 -> 144
A15: 147 | V15: =SUM(B15:H15) -> 0 | W15: =SUM(I15:U15) -> 0 | X15: =W15+V15 -> 0 | Z15: 147 | AA15: =X15 -> 0
A16: RTZ148 | Q16: 144 | V16: =SUM(B16:H16) -> 0 | W16: =SUM(I16:U16) -> 144 | X16: =W16+V16 -> 144 | Z16: RTZ148 | AA16: =X16 -> 144
A17: סרבי M02P1 | V17: =SUM(B17:H17) -> 0 | W17: =SUM(I17:U17) -> 0 | X17: =W17+V17 -> 0 | Z17: סרבי M02P1 | AA17: =X17 -> 0
A18: ברוס מאג | V18: =SUM(B18:H18) -> 0 | W18: =SUM(I18:U18) -> 0 | X18: =W18+V18 -> 0 | Z18: 984 | AA18: =X18 -> 0
A19: 984 | R19: 144 | V19: =SUM(B19:H19) -> 0 | W19: =SUM(I19:U19) -> 144 | X19: =W19+V19 -> 144 | Z19: 557 | AA19: =X19 -> 144
A20: 557 | V20: =SUM(B20:H20) -> 0 | W20: =SUM(I20:U20) -> 0 | X20: =W20+V20 -> 0 | Z20: M7 אחוד | AA20: =SUM(X22:X32) -> 142
Z21: M7 פרוד | AA21: =SUM(X33:X35) -> 252
A22: M7 אחוד 1-94/99 | B22: 15 | C22: 11 | D22: 4 | E22: 16 | F22: 8 | G22: 2 | V22: =SUM(B22:H22) -> 56 | W22: =SUM(I22:U22) -> 0 | X22: =W22+V22 -> 56 | Z22: M9 | AA22: =SUM(X37:X45) -> 207
A23: M7 אחוד 1-98 | V23: =SUM(B23:H23) -> 0 | W23: =SUM(I23:U23) -> 0 | X23: =W23+V23 -> 0 | Z23: M10 | AA23: =X47 -> 0
A24: M7 אחוד 01-98 | V24: =SUM(B24:H24) -> 0 | W24: =SUM(I24:U24) -> 0 | X24: =W24+V24 -> 0 | Z24: M231 | AA24: =X48 -> 284
A25: M7 אחוד 3-94/99 | V25: =SUM(B25:H25) -> 0 | W25: =SUM(I25:U25) -> 0 | X25: =W25+V25 -> 0 | Z25: תחלים | AA25: =X49 -> 855
A26: M7 אחוד1-93/97 | V26: =SUM(B26:H26) -> 0 | W26: =SUM(I26:U26) -> 0 | X26: =W26+V26 -> 0
A27: M7 אחוד 1-94/99 | V27: =SUM(B27:H27) -> 0 | W27: =SUM(I27:U27) -> 0 | X27: =W27+V27 -> 0
A28: M7 אחוד 2-93/97 | V28: =SUM(B28:H28) -> 0 | W28: =SUM(I28:U28) -> 0 | X28: =W28+V28 -> 0
A29: M7 אחוד 2-99 | V29: =SUM(B29:H29) -> 0 | W29: =SUM(I29:U29) -> 0 | X29: =W29+V29 -> 0
A30: M7 אחוד 1-94/99 | V30: =SUM(B30:H30) -> 0 | W30: =SUM(I30:U30) -> 0 | X30: =W30+V30 -> 0
A31: M7 אחוד 2/24 | B31: 8 | C31: 12 | D31: 12 | E31: 12 | F31: 6 | G31: 12 | J31: 24 | V31: =SUM(B31:H31) -> 62 | W31: =SUM(I31:U31) -> 24 | X31: =W31+V31 -> 86
A32: M7אחוד 1-24 | V32: =SUM(B32:H32) -> 0 | W32: =SUM(I32:U32) -> 0 | X32: =W32+V32 -> 0
A33: M7 פרוד 1-93/97 | V33: =SUM(B33:H33) -> 0 | W33: =SUM(I33:U33) -> 0 | X33: =W33+V33 -> 0
A34: M7 פרוד2-94/97 | R34: 144 | V34: =SUM(B34:H34) -> 0 | W34: =SUM(I34:U34) -> 144 | X34: =W34+V34 -> 144
A35: פרוד 1-98 | S35: 108 | V35: =SUM(B35:H35) -> 0 | W35: =SUM(I35:U35) -> 108 | X35: =W35+V35 -> 108
A37: M9 4-99/02 | V37: =SUM(B37:H37) -> 0 | W37: =SUM(I37:U37) -> 0 | X37: =W37+V37 -> 0
A38: M9 5-96/84 | V38: =SUM(B38:H38) -> 0 | W38: =SUM(I38:U38) -> 0 | X38: =W38+V38 -> 0
A39: M9 10-99/84 | V39: =SUM(B39:H39) -> 0 | W39: =SUM(I39:U39) -> 0 | X39: =W39+V39 -> 0
A40: M9 5-99/85 | V40: =SUM(B40:H40) -> 0 | W40: =SUM(I40:U40) -> 0 | X40: =W40+V40 -> 0
A41: M9 1-09 | V41: =SUM(B41:H41) -> 0 | W41: =SUM(I41:U41) -> 0 | X41: =W41+V41 -> 0
...

Sheet צילומי מסך
F27: שצל ירידה ב
G28: ספור בלי ב

Sheet עותק של ריכוז גדודי
A1: 9294 | B1: דוח תחמושת | C1: סוללה א | D1: סוללה ב | E1: סוללה ג | F1: סוללה ד - זעורה | H1: סה"כ גדוד | K1: שצ''ל ירי | L1: סוללה א | M1: סוללה ב | N1: סוללה ג | P1: סה"כ גדוד | S1: דוח תחמושת מעודכן | T1: סוללה א | U1: סוללה ב | V1: סוללה ג | X1: סה"כ גדוד | Z1: ייפתח
C2: כפר גלעדי | D2: גומא | E2: יחמור | L2: כפר גלעדי | M2: גומא | N2: אלקוץ | T2: כפר גלעדי | U2: גומא | V2: אלקוץ | Z2: קרקע | AA2: בונקר
B3: נפיץ M107 | C3: =' תחמושת סוללה א'!Z2 -> 124 | D3: ='תמחושת סוללה ב'!X2 -> 181 | E3: 130 | F3: #REF! | H3: =E3+D3+C3 -> 435 | K3: נפיץ M107 | N3: =' - אלקוש ג'!AJ2 | P3: =N3+M3+L3 -> 0 | S3: נפיץ M107 | T3: =C3-L3 -> 124 | U3: =D3-M3 -> 181 | V3: =E3-N3 -> 130 | X3: =V3+U3+T3 -> 435 | Z3: 17 | AA3: 48 | AB3: =SUM(Z3:AA3) -> 65
B4: נפיץ M107A3 / סרבי | C4: =' תחמושת סוללה א'!Z3 -> 36 | D4: ='תמחושת סוללה ב'!X3 -> 53 | E4: 236 | F4: #REF! | H4: =E4+D4+C4 -> 325 | K4: נפיץ M107A3 / סרבי | N4: =' - אלקוש ג'!AJ3 | P4: =N4+M4+L4 -> 0 | S4: נפיץ M107A3 / סרבי | T4: =C4-L4 -> 36 | U4: =D4-M4 -> 53 | V4: =E4-N4 -> 236 | X4: =V4+U4+T4 -> 325 | Z4: 0 | AA4: 0 | AB4: =SUM(Z4:AA4) -> 0
B5: נפיץ M795 | C5: =' תחמושת סוללה א'!Z4 -> 137 | D5: ='תמחושת סוללה ב'!X4 -> 209 | E5: 126 | F5: #REF! | H5: =E5+D5+C5 -> 472 | K5: נפיץ M795 | N5: =' - אלקוש ג'!AJ4 | P5: =N5+M5+L5 -> 0 | S5: נפיץ M795 | T5: =C5-L5 -> 137 | U5: =D5-M5 -> 209 | V5: =E5-N5 -> 126 | X5: =V5+U5+T5 -> 472 | Z5: 124 | AA5: 148 | AB5: =SUM(Z5:AA5) -> 272
B6: תאורה M485 | C6: =' תחמושת סוללה א'!Z5 -> 24 | D6: ='תמחושת סוללה ב'!X5 -> 146 | E6: 48 | F6: #REF! | H6: =E6+D6+C6 -> 218 | K6: תאורה M485 | N6: =' - אלקוש ג'!AJ5 | P6: =N6+M6+L6 -> 0 | S6: תאורה M485 | T6: =C6-L6 -> 24 | U6: =D6-M6 -> 146 | V6: =E6-N6 -> 48 | X6: =V6+U6+T6 -> 218 | Z6: 76 | AA6: 176 | AB6: =SUM(Z6:AA6) -> 252
B7: עשן M825 | C7: =' תחמושת סוללה א'!Z6 -> 105 | D7: ='תמחושת סוללה ב'!X6 -> 75 | E7: 0 | F7: #REF! | H7: =E7+D7+C7 -> 180 | K7: עשן M825 | N7: =' - אלקוש ג'!AJ6 | P7: =N7+M7+L7 -> 0 | S7: עשן M825 | T7: =C7-L7 -> 105 | U7: =D7-M7 -> 75 | V7: =E7-N7 -> 0 | X7: =V7+U7+T7 -> 180 | Z7: 38 | AA7: 144 | AB7: =SUM(Z7:AA7) -> 182
B8: דמוי נפיץ | C8: =' תחמושת סוללה א'!Z7 -> 24 | D8: ='תמחושת סוללה ב'!X7 -> 0 | E8: 0 | F8: #REF! | H8: =E8+D8+C8 -> 24 | K8: דמוי נפיץ | N8: =' - אלקוש ג'!AJ7 | P8: =N8+M8+L8 -> 0 | S8: דמוי נפיץ | T8: =C8-L8 -> 24 | U8: =D8-M8 -> 0 | V8: =E8-N8 -> 0 | X8: =V8+U8+T8 -> 24 | Z8: 14 | AA8: 0 | AB8: =SUM(Z8:AA8) -> 14
B9: עשן הפלטה M150 | C9: =' תחמושת סוללה א'!Z8 -> 0 | D9: ='תמחושת סוללה ב'!X8 -> 144 | E9: 144 | F9: #REF! | H9: =E9+D9+C9 -> 288 | K9: עשן הפלטה M150 | N9: =' - אלקוש ג'!AJ8 | P9: =N9+M9+L9 -> 0 | S9: עשן הפלטה M150 | T9: =C9-L9 -> 0 | U9: =D9-M9 -> 144 | V9: =E9-N9 -> 144 | X9: =V9+U9+T9 -> 288 | Z9: 123 | AA9: 165 | AB9: =SUM(Z9:AA9) -> 288
B10: נפיץ ארוך טווח M401 | C10: =' תחמושת סוללה א'!Z9 -> 0 | D10: ='תמחושת סוללה ב'!X9 -> 0 | E10: 0 | F10: #REF! | H10: =E10+D10+C10 -> 0 | K10: נפיץ ארוך טווח M401 | N10: =' - אלקוש ג'!AJ9 | P10: =N10+M10+L10 -> 0 | S10: נפיץ ארוך טווח M401 | T10: =C10-L10 -> 0 | U10: =D10-M10 -> 0 | V10: =E10-N10 -> 0 | X10: =V10+U10+T10 -> 0 | Z10: 0 | AA10: 0 | AB10: =SUM(Z10:AA10) -> 0
B11: M999 | C11: =' תחמושת סוללה א'!Z10 -> 0 | D11: ='תמחושת סוללה ב'!X10 -> 0 | E11: 0 | F11: #REF! | H11: =E11+D11+C11 -> 0 | K11: M999 | N11: =' - אלקוש ג'!AJ10 | P11: =N11+M11+L11 -> 0 | S11: M999 | T11: =C11-L11 -> 0 | U11: =D11-M11 -> 0 | V11: =E11-N11 -> 0 | X11: =V11+U11+T11 -> 0 | Z11: 0 | AA11: 0 | AB11: =SUM(Z11:AA11) -> 0
B12: 582 | C12: =' תחמושת סוללה א'!Z11 -> 156 | D12: ='תמחושת סוללה ב'!X11 -> 161 | E12: 197? | F12: #REF! | H12: =E12+D12+C12 -> #VALUE! | K12: 582 | N12: =' - אלקוש ג'!AJ11 | P12: =N12+M12+L12 -> 0 | S12: 582 | T12: =C12-L12 -> 156 | U12: =D12-M12 -> 161 | V12: =E12-N12 -> #VALUE! | X12: =V12+U12+T12 -> #VALUE! | Z12: 190 | AA12: 9 | AB12: =SUM(Z12:AA12) -> 199
B13: 739 | C13: =' תחמושת סוללה א'!Z12 -> 15 | D13: ='תמחושת סוללה ב'!X12 -> 55 | E13: 31? | F13: #REF! | H13: =E13+D13+C13 -> #VALUE! | K13: 739 | N13: =' - אלקוש ג'!AJ12 | P13: =N13+M13+L13 -> 0 | S13: 739 | T13: =C13-L13 -> 15 | U13: =D13-M13 -> 55 | V13: =E13-N13 -> #VALUE! | X13: =V13+U13+T13 -> #VALUE! | Z13: 77 | AA13: 61 | AB13: =SUM(Z13:AA13) -> 138
B14: 137 | C14: =' תחמושת סוללה א'!Z13 -> 94 | D14: ='תמחושת סוללה ב'!X13 -> 68 | E14: 0 | F14: #REF! | H14: =E14+D14+C14 -> 162 | K14: 137 | N14: =' - אלקוש ג'!AJ13 | P14: =N14+M14+L14 -> 0 | S14: 137 | T14: =C14-L14 -> 94 | U14: =D14-M14 -> 68 | V14: =E14-N14 -> 0 | X14: =V14+U14+T14 -> 162 | Z14: 205 | AA14: 60 | AB14: =SUM(Z14:AA14) -> 265
B15: 762 | C15: =' תחמושת סוללה א'!Z14 -> 0 | D15: ='תמחושת סוללה ב'!X14 -> 272 | E15: 153 | F15: #REF! | H15: =E15+D15+C15 -> 425 | K15: 762 | N15: =' - אלקוש ג'!AJ14 | P15: =N15+M15+L15 -> 0 | S15: 762 | T15: =C15-L15 -> 0 | U15: =D15-M15 -> 272 | V15: =E15-N15 -> 153 | X15: =V15+U15+T15 -> 425 | Z15: 0 | AA15: 242 | AB15: =SUM(Z15:AA15) -> 242
B16: 147 | C16: =' תחמושת סוללה א'!Z15 -> 0 | D16: ='תמחושת סוללה ב'!X15 -> 0 | E16: 0 | F16: #REF! | H16: =E16+D16+C16 -> 0 | K16: 147 | N16: =' - אלקוש ג'!AJ15 | P16: =N16+M16+L16 -> 0 | S16: 147 | T16: =C16-L16 -> 0 | U16: =D16-M16 -> 0 | V16: =E16-N16 -> 0 | X16: =V16+U16+T16 -> 0 | Z16: 0 | AA16: 0 | AB16: =SUM(Z16:AA16) -> 0
B17: RTZ148 | C17: =' תחמושת סוללה א'!Z16 -> 136 | D17: ='תמחושת סוללה ב'!X16 -> 96 | E17: 222 | F17: #REF! | H17: =E17+D17+C17 -> 454 | K17: RTZ148 | N17: =' - אלקוש ג'!AJ16 | P17: =N17+M17+L17 -> 0 | S17: RTZ148 | T17: =C17-L17 -> 136 | U17: =D17-M17 -> 96 | V17: =E17-N17 -> 222 | X17: =V17+U17+T17 -> 454 | Z17: 0 | AA17: 0 | AB17: =SUM(Z17:AA17) -> 0
B18: סרבי M02P1 | C18: =' תחמושת סוללה א'!Z17 -> 0 | D18: ='תמחושת סוללה ב'!X17 -> 0 | E18: 0 | F18: #REF! | H18: =E18+D18+C18 -> 0 | K18: סרבי M02P1 | N18: =' - אלקוש ג'!AJ17 | P18: =N18+M18+L18 -> 0 | S18: סרבי M02P1 | T18: =C18-L18 -> 0 | U18: =D18-M18 -> 0 | V18: =E18-N18 -> 0 | X18: =V18+U18+T18 -> 0 | Z18: 0 | AA18: 0 | AB18: =SUM(Z18:AA18) -> 0
B19: 984 | C19: =' תחמושת סוללה א'!Z19 -> 2 | D19: ='תמחושת סוללה ב'!X18 -> 93 | E19: 0 | H19: =E19+D19+C19 -> 95 | K19: 984 | S19: 984 | T19: =C19-L19 -> 2 | U19: =D19-M19 -> 93 | V19: =E19-N19 -> 0 | X19: =V19+U19+T19 -> 95 | Z19: 0 | AA19: 0 | AB19: =SUM(Z19:AA19) -> 0
B20: 557 | C20: =' תחמושת סוללה א'!Z18 -> 0 | D20: ='תמחושת סוללה ב'!X19 -> 0 | E20: 0? | F20: #REF! | H20: =E20+D20+C20 -> #VALUE! | K20: 557 | N20: =' - אלקוש ג'!AJ18 | P20: =N20+M20+L20 -> 0 | S20: 557 | T20: =C20-L20 -> 0 | U20: =D20-M20 -> 0 | V20: =E20-N20 -> #VALUE! | X20: =V20+U20+T20 -> #VALUE! | Z20: 14 | AA20: 23 | AB20: =SUM(Z20:AA20) -> 37
B21: M7 אחוד | C21: =' תחמושת סוללה א'!Z20 -> 1 | D21: ='תמחושת סוללה ב'!X20 -> 277 | E21: 194 | F21: #REF! | H21: =E21+D21+C21 -> 472 | K21: M7 אחוד | N21: =' - אלקוש ג'!AJ20 | P21: =N21+M21+L21 -> 0 | S21: M7 אחוד | T21: =C21-L21 -> 1 | U21: =D21-M21 -> 277 | V21: =E21-N21 -> 194 | X21: =V21+U21+T21 -> 472 | Z21: 144 | AA21: 347 | AB21: =SUM(Z21:AA21) -> 491
B22: M7 פרוד | C22: =' תחמושת סוללה א'!Z21 -> 164 | D22: ='תמחושת סוללה ב'!X21 -> 157 | E22: 120 | F22: #REF! | H22: =E22+D22+C22 -> 441 | K22: M7 פרוד | N22: =' - אלקוש ג'!AJ21 | P22: =N22+M22+L22 -> 0 | S22: M7 פרוד | T22: =C22-L22 -> 164 | U22: =D22-M22 -> 157 | V22: =E22-N22 -> 120 | X22: =V22+U22+T22 -> 441 | Z22: 69 | AA22: 49 | AB22: =SUM(Z22:AA22) -> 118
B23: M9 | C23: =' תחמושת סוללה א'!Z22 -> 285 | D23: ='תמחושת סוללה ב'!X22 -> 332 | E23: 188 | F23: #REF! | H23: =E23+D23+C23 -> 805 | K23: M9 | N23: =' - אלקוש ג'!AJ22 | P23: =N23+M23+L23 -> 0 | S23: M9 | T23: =C23-L23 -> 285 | U23: =D23-M23 -> 332 | V23: =E23-N23 -> 188 | X23: =V23+U23+T23 -> 805 | Z23: 187 | AA23: 1 | AB23: =SUM(Z23:AA23) -> 188
B24: M10 | C24: =' תחמושת סוללה א'!Z23 -> 0 | D24: ='תמחושת סוללה ב'!X23 -> 0 | E24: 0 | F24: #REF! | H24: =E24+D24+C24 -> 0 | K24: M10 | N24: =' - אלקוש ג'!AJ23 | P24: =N24+M24+L24 -> 0 | S24: M10 | T24: =C24-L24 -> 0 | U24: =D24-M24 -> 0 | V24: =E24-N24 -> 0 | X24: =V24+U24+T24 -> 0 | Z24: 21 | AA24: 124 | AB24: =SUM(Z24:AA24) -> 145
B25: M231 | C25: =' תחמושת סוללה א'!Z24 -> 76 | D25: ='תמחושת סוללה ב'!X24 -> 0 | E25: 0 | F25: #REF! | H25: =E25+D25+C25 -> 76 | K25: M231 | N25: =' - אלקוש ג'!AJ24 | P25: =N25+M25+L25 -> 0 | S25: M231 | T25: =C25-L25 -> 76 | U25: =D25-M25 -> 0 | V25: =E25-N25 -> 0 | X25: =V25+U25+T25 -> 76 | Z25: 138 | AA25: 268 | AB25: =SUM(Z25:AA25) -> 406
B26: תחלים | C26: =' תחמושת סוללה א'!Z25 -> 466 | D26: ='תמחושת סוללה ב'!X25 -> 320 | E26: 500 | F26: #REF! | H26: =E26+D26+C26 -> 1286 | K26: תחלים | N26: =' - אלקוש ג'!AJ25 | P26: =N26+M26+L26 -> 0 | S26: תחלים | T26: =C26-L26 -> 466 | U26: =D26-M26 -> 320 | V26: =E26-N26 -> 500 | X26: =V26+U26+T26 -> 1286 | Z26: 440 | AA26: 480 | AB26: =SUM(Z26:AA26) -> 920
C27: =NOW() -> 46091.382 | L27: =NOW() -> 46091.382 | T27: =NOW() -> 46091.382 | Y27: M5 אחוד | Z27: 0 | AA27: 44 | AB27: =SUM(Z27:AA27) -> 44
C29: לא מעודכן ירי 5.3.26
C32: גלעדי | D32: גומה | E32: יחמור | G32: ייפתח | L32: גומא | M32: יחמור | N32: ייפתח | R32: גומא | S32: יחמור | T32: ייפתח | W32: גומא | X32: יחמור | Y32: ייפתח
B33: נפיץ M107 | C33: 192 | D33: 217 | E33: 237 | F33: #REF! | G33: 65 | K33: נפיץ M107 | L33: 217 | M33: 225 | N33: 65 | Q33: נפיץ M107 | R33: 180 | S33: 201 | T33: 65 | V33: נפיץ M107 | W33: 180 | X33: 201 | Y33: 65
B34: נפיץ M107A3 / סרבי | C34: 47 | D34: 139 | E34: 144 | F34: #REF! | G34: 0 | K34: נפיץ M107A3 / סרבי | L34: 133 | M34: 85 | N34: 144 | Q34: נפיץ M107A3 / סרבי | R34: 84 | S34: 55 | T34: 144 | V34: נפיץ M107A3 / סרבי | W34: 84 | X34: 55 | Y34: 144
B35: נפיץ M795 | C35: 137 | D35: 193 | E35: 126 | F35: #REF! | G35: 272 | K35: נפיץ M795 | L35: 193 | M35: 126 | N35: 265 | Q35: נפיץ M795 | R35: 209 | S35: 126 | T35: 198 | V35: נפיץ M795 | W35: 209 | X35: 126 | Y35: 198
B36: תאורה M485 | C36: 24 | D36: 154 | E36: 48 | F36: #REF! | G36: 252 | K36: תאורה M485 | L36: 154 | M36: 158 | N36: 254 | Q36: תאורה M485 | R36: 154 | S36: 158 | T36: 251 | V36: תאורה M485 | W36: 154 | X36: 158 | Y36: 251
B37: עשן M825 | C37: 105 | D37: 132 | E37: 0 | F37: #REF! | G37: 182 | K37: עשן M825 | L37: 428 | M37: 0 | N37: 182 | Q37: עשן M825 | R37: 120 | S37: 0 | T37: 182 | V37: עשן M825 | W37: 120 | X37: 0 | Y37: 182
B38: דמוי נפיץ | C38: 24 | D38: 0 | E38: 0 | F38: #REF! | G38: 14 | K38: דמוי נפיץ | L38: 0 | M38: 0 | N38: 14 | Q38: דמוי נפיץ | R38: 0 | S38: 0 | T38: 14 | V38: דמוי נפיץ | W38: 0 | X38: 0 | Y38: 14
B39: עשן הפלטה M150 | C39: 0 | D39: 0 | E39: 144 | F39: #REF! | G39: 288 | K39: עשן הפלטה M150 | L39: 0 | M39: 156 | N39: 286 | Q39: עשן הפלטה M150 | R39: 288 | S39: 139 | T39: 286 | V39: עשן הפלטה M150 | W39: 144 | X39: 139 | Y39: 286
B40: נפיץ ארוך טווח M401 | C40: 0 | D40: 0 | E40: 0 | F40: #REF! | G40: 0 | K40: נפיץ ארוך טווח M401 | L40: 0 | M40: 0 | N40: 0 | Q40: נפיץ ארוך טווח M401 | R40: 0 | S40: 0 | T40: 0 | V40: נפיץ ארוך טווח M401 | W40: 0 | X40: 0 | Y40: 0
B41: M999 | C41: 0 | D41: 0 | E41: 0 | F41: #REF! | G41: 0 | K41: M999 | L41: 0 | M41: 0 | N41: 0 | Q41: M999 | R41: 0 | S41: 0 | T41: 0 | V41: M999 | W41: 0 | X41: 0 | Y41: 0
B42: 582 | C42: 156 | D42: 150 | E42: 197? | F42: #REF! | G42: 199 | K42: 582 | L42: 150 | M42: 150 | N42: 202 | Q42: 582 | R42: 142 | S42: 150 | T42: 182 | V42: 582 | W42: 142 | X42: 150 | Y42: 182
B43: 739 | C43: 16 | D43: 55 | E43: 31? | F43: #REF! | G43: 138 | K43: 739 | L43: 55 | M43: 12 | N43: 86 | Q43: 739 | R43: 33 | S43: 12 | T43: 64 | V43: 739 | W43: 33 | X43: 0 | Y43: 64
...
